<?xml version="1.0" encoding="UTF-8"?>
<!-- Generated by org.testng.reporters.JUnitReportReporter -->
<testsuite hostname="hugo-pc" failures="0" tests="13" name="Lecture9.Lecture9_2Test" time="9.510" errors="1" timestamp="2022-10-17T20:57:25 MSK" skipped="5">
  <testcase classname="Lecture9.Lecture9_2Test" name="test2" time="0.000"/>
  <system-out/>
  <testcase classname="Lecture9.Lecture9_2Test" name="test3" time="1.061">
    <error message="Method Lecture9.Lecture9_2Test.test3() didn&#039;t finish within the time-out 1000" type="org.testng.internal.thread.ThreadTimeoutException">
      <![CDATA[org.testng.internal.thread.ThreadTimeoutException: Method Lecture9.Lecture9_2Test.test3() didn't finish within the time-out 1000
at java.base@11.0.15.1/java.lang.Thread.sleep(Native Method)
at app//Lecture9.Lecture9_2Test.pause(Lecture9_2Test.java:58)
at app//Lecture9.Lecture9_2Test.test3(Lecture9_2Test.java:24)
at java.base@11.0.15.1/jdk.internal.reflect.NativeMethodAccessorImpl.invoke0(Native Method)
at java.base@11.0.15.1/jdk.internal.reflect.NativeMethodAccessorImpl.invoke(NativeMethodAccessorImpl.java:62)
at java.base@11.0.15.1/jdk.internal.reflect.DelegatingMethodAccessorImpl.invoke(DelegatingMethodAccessorImpl.java:43)
at java.base@11.0.15.1/java.lang.reflect.Method.invoke(Method.java:566)
at app//org.testng.internal.invokers.MethodInvocationHelper.invokeMethod(MethodInvocationHelper.java:139)
at app//org.testng.internal.invokers.InvokeMethodRunnable.runOne(InvokeMethodRunnable.java:47)
at app//org.testng.internal.invokers.InvokeMethodRunnable.call(InvokeMethodRunnable.java:76)
at app//org.testng.internal.invokers.InvokeMethodRunnable.call(InvokeMethodRunnable.java:11)
at java.base@11.0.15.1/java.util.concurrent.FutureTask.run(FutureTask.java:264)
at java.base@11.0.15.1/java.util.concurrent.ThreadPoolExecutor.runWorker(ThreadPoolExecutor.java:1128)
at java.base@11.0.15.1/java.util.concurrent.ThreadPoolExecutor$Worker.run(ThreadPoolExecutor.java:628)
at java.base@11.0.15.1/java.lang.Thread.run(Thread.java:834)
]]>
    </error>
  </testcase> <!-- test3 -->
  <system-out/>
  <testcase classname="Lecture9.Lecture9_2Test" name="test4" time="0.000">
    <skipped/>
  </testcase> <!-- test4 -->
  <system-out/>
  <testcase classname="Lecture9.Lecture9_2Test" name="test5" time="1.015"/>
  <system-out/>
  <testcase classname="Lecture9.Lecture9_2Test" name="test5" time="1.046"/>
  <system-out/>
  <testcase classname="Lecture9.Lecture9_2Test" name="test5" time="1.029"/>
  <system-out/>
  <testcase classname="Lecture9.Lecture9_2Test" name="test5" time="1.046"/>
  <system-out/>
  <testcase classname="Lecture9.Lecture9_2Test" name="test5" time="1.030"/>
  <system-out/>
  <testcase classname="Lecture9.Lecture9_2Test" name="test6" time="1.035">
    <skipped/>
  </testcase> <!-- test6 -->
  <system-out/>
  <testcase classname="Lecture9.Lecture9_2Test" name="test6" time="0.103"/>
  <system-out/>
  <testcase classname="Lecture9.Lecture9_2Test" name="test6" time="1.115">
    <skipped/>
  </testcase> <!-- test6 -->
  <system-out/>
  <testcase classname="Lecture9.Lecture9_2Test" name="test6" time="1.030">
    <skipped/>
  </testcase> <!-- test6 -->
  <system-out/>
  <testcase classname="Lecture9.Lecture9_2Test" name="test1">
    <skipped/>
  </testcase> <!-- test1 -->
  <system-out/>
</testsuite> <!-- Lecture9.Lecture9_2Test -->
